<?xml version="1.0" ?>
<!-- =================================================================================== -->
<!-- |    This document was autogenerated by xacro from /home/meditab/Desktop/ROS2/src/my_robot_description/urdf/dosecar.urdf.xacro | -->
<!-- |    EDITING THIS FILE BY HAND IS NOT RECOMMENDED                                 | -->
<!-- =================================================================================== -->
<robot name="my_robot">
  <material name="blue">
    <color rgba="0 0 0.5 1"/>
  </material>
  <material name="grey">
    <color rgba="0.5 0.5 0.5 1"/>
  </material>
  <link name="base_footprint"/>
  <link name="base_link">
    <visual>
      <geometry>
       <mesh filename="package://my_robot_agv/models/agv/meshes/camera.obj" scale="1 1 1"/>
      </geometry>
      <origin rpy="0 0 0" xyz="0 0 0.1"/>
      <material name="grey"/>
    </visual>
    <inertial>
      <origin rpy="0 0 0" xyz="0 0 0.1"/>
      <mass value="5.0"/>
      <inertia ixx="0.6666666666666667" ixy="0" ixz="0" iyy="0.8666666666666667" iyz="0" izz="0.3333333333333334"/>
    </inertial>
    <collision>
      <geometry>
        <box size="0.6 0.4 0.2"/>
      </geometry>
      <origin rpy="0 0 0" xyz="0 0 0.1"/>
    </collision>
  </link>
  <link name="right_wheel_link">
    <visual>
      <geometry>
        <cylinder length="0.05" radius="0.1"/>
      </geometry>
      <origin rpy="1.5707963267948966 0 0" xyz="0 0 0"/>
      <material name="grey"/>
    </visual>
    <collision>
      <geometry>
        <cylinder length="0.05" radius="0.1"/>
      </geometry>
      <origin rpy="1.5707963267948966 0 0" xyz="0 0 0"/>
    </collision>
    <inertial>
      <origin rpy="1.5707963267948966 0 0" xyz="0 0 0"/>
      <mass value="3.0"/>
      <inertia ixx="0.010000000000000002" ixy="0" ixz="0" iyy="0.010000000000000002" iyz="0" izz="0.015000000000000003"/>
    </inertial>
  </link>
  <link name="left_wheel_link">
    <visual>
      <geometry>
        <cylinder length="0.05" radius="0.1"/>
      </geometry>
      <origin rpy="1.5707963267948966 0 0" xyz="0 0 0"/>
      <material name="grey"/>
    </visual>
    <collision>
      <geometry>
        <cylinder length="0.05" radius="0.1"/>
      </geometry>
      <origin rpy="1.5707963267948966 0 0" xyz="0 0 0"/>
    </collision>
    <inertial>
      <origin rpy="1.5707963267948966 0 0" xyz="0 0 0"/>
      <mass value="3.0"/>
      <inertia ixx="0.010000000000000002" ixy="0" ixz="0" iyy="0.010000000000000002" iyz="0" izz="0.015000000000000003"/>
    </inertial>
  </link>
  <link name="caster_wheel_link">
    <visual>
      <geometry>
        <sphere radius="0.05"/>
      </geometry>
      <origin rpy="0 0 0" xyz="0 0 0"/>
      <material name="grey"/>
    </visual>
    <collision>
      <geometry>
        <sphere radius="0.05"/>
      </geometry>
      <origin rpy="0 0 0" xyz="0 0 0"/>
    </collision>
    <inertial>
      <origin rpy="0 0 0" xyz="0 0 0"/>
      <mass value="0.5"/>
      <inertia ixx="0.0005000000000000001" ixy="0" ixz="0" iyy="0.0005000000000000001" iyz="0" izz="0.0005000000000000001"/>
    </inertial>
  </link>
  <joint name="base_joint" type="fixed">
    <parent link="base_footprint"/>
    <child link="base_link"/>
    <origin rpy="0 0 0" xyz="0 0 0.1"/>
  </joint>
  <joint name="base_right_wheel_joint" type="continuous">
    <parent link="base_link"/>
    <child link="right_wheel_link"/>
    <origin rpy="0 0 0" xyz="-0.15 -0.225 0"/>
    <axis xyz="0 1 0"/>
  </joint>
  <joint name="base_left_wheel_joint" type="continuous">
    <parent link="base_link"/>
    <child link="left_wheel_link"/>
    <origin rpy="0 0 0" xyz="-0.15 0.225 0"/>
    <axis xyz="0 1 0"/>
  </joint>
  <joint name="base_caster_wheel_joint" type="fixed">
    <parent link="base_link"/>
    <child link="caster_wheel_link"/>
    <origin rpy="0 0 0" xyz="0.19999999999999998 0 -0.05"/>
  </joint>
  <gazebo reference="base_link">
    <material>Gazebo/Blue</material>
  </gazebo>
  <gazebo reference="right_wheel_link">
    <material>Gazebo/Grey</material>
  </gazebo>
  <gazebo reference="left_wheel_link">
    <material>Gazebo/Grey</material>
  </gazebo>
  <gazebo reference="caster_wheel_link">
    <material>Gazebo/Grey</material>
    <mu1 value="0.1"/>
    <mu2 value="0.1"/>
  </gazebo>
  <gazebo>
    <plugin filename="libgazebo_ros_diff_drive.so" name="diff_drive_control">
      <!-- <ros> -->
      <!-- Add a namespace -->
      <!-- <namespace>/test</namespace> -->
      <!-- </ros> -->
      <!-- Update rate in Hz -->
      <update_rate>50</update_rate>
      <!-- wheels -->
      <left_joint>base_left_wheel_joint</left_joint>
      <right_joint>base_right_wheel_joint</right_joint>
      <!-- kinematics -->
      <wheel_separation>0.45</wheel_separation>
      <wheel_diameter>0.2</wheel_diameter>
      <!-- limits
        <max_wheel_torque>20</max_wheel_torque>
        <max_wheel_acceleration>1.0</max_wheel_acceleration> -->
      <!-- input -->
      <!-- <command_topic>cmd_vel</command_topic> -->
      <!-- output -->
      <publish_odom>true</publish_odom>
      <publish_odom_tf>true</publish_odom_tf>
      <publish_wheel_tf>true</publish_wheel_tf>
      <odometry_topic>odom</odometry_topic>
      <odometry_frame>odom</odometry_frame>
      <robot_base_frame>base_footprint</robot_base_frame>
    </plugin>
  </gazebo>
  <material name="camera_material">
    <color rgba="0.0 1.0 1.0 1.0"/>
  </material>
  <link name="camera_link">
    <visual>
      <geometry>
        <box size="0.1 0.1 0.05"/>
      </geometry>
      <material name="camera_material"/>
    </visual>
    <collision>
      <geometry>
        <box size="0.1 0.1 0.05"/>
      </geometry>
    </collision>
    <inertial>
      <origin rpy="0 0 0" xyz="0 0 0"/>
      <mass value="0.1"/>
      <inertia ixx="0.00010416666666666669" ixy="0" ixz="0" iyy="0.0001666666666666667" iyz="0" izz="0.00010416666666666669"/>
    </inertial>
  </link>
  <joint name="base_camera_joint" type="fixed">
    <origin rpy="0.0 1.57 0.0" xyz="0.0 0 0.05"/>
    <parent link="base_link"/>
    <child link="camera_link"/>
  </joint>
  <link name="camera_link_optical">
    </link>
  <joint name="camera_optical_joint" type="fixed">
    <origin rpy="-1.5707963267948966 0 -1.5707963267948966" xyz="0 0 0"/>
    <parent link="camera_link"/>
    <child link="camera_link_optical"/>
  </joint>
  <gazebo reference="camera_link">
    <material>Gazebo/Red</material>
    <sensor name="camera_sensor" type="camera">
      <pose>0 0 0 0 0 0</pose>
      <visualize>true</visualize>
      <update_rate>10.0</update_rate>
      <camera name="camera">
        <image>
          <width>640</width>
          <height>480</height>
          <format>R8G8B8</format>
        </image>
        <clip>
          <near>0.05</near>
          <far>8</far>
        </clip>
      </camera>
      <plugin filename="libgazebo_ros_camera.so" name="camera_controller">
        <cameraName>camera</cameraName>
        <frame_name>camera_link_optical</frame_name>
      </plugin>
    </sensor>
  </gazebo>
</robot>
